Workbook

Sheet README
A1: Peer slides: backup data, evidence and checks
A2: Every derived number is a live formula. Sources and verbatim evidence are on the Evidence sheet.
A4: Slide 1 | B4: S1_Scorecard: College Scorecard institution-level file, release of June 10, 2026, same filters as the original slide (1,527 institutions).
A5: Slide 2 | B5: S2_Survey: Inside Higher Ed business-officer survey 2015-2026, re-read from the report PDFs; the original slide's values and the differences are shown.
A6: Slide 3 | B6: S3_FY25: FY25 audited statements (plus Form 990 / MD&A where the audited statements combine salaries and benefits). S3_Sensitivity, S3_FY23_Recalc and S3_Enrollment test the assumptions.
A7: Evidence | B7: Verbatim source rows and document links for each FY25 figure.
A8: Checks | B8: Every test run and every disconnect found, with status.
A9: Data_needed | B9: What is still open (Harvard FY25 report; Northeastern headcount confirmation; Penn / Stanford salaries and wages).

Sheet S1_Scorecard
A1: Slide 1: net price vs median earnings 10 years after entry (College Scorecard, June 10, 2026 release)
A2: Earnings: pooled AY2009-10 / 2010-11 entry cohorts measured CY2020-21, 2022 dollars. Net price: AY2023-24. Rank = 1 + number of institutions with higher earnings.
A4: UNITID | B4: Institution | C4: City | D4: State | E4: Control | F4: Avg annual net price (NPT4) | G4: Median earnings, 10th yr after entry | H4: Rank by earnings | I4: Highlight | J4: Private net price | K4: Private earnings | M4: Summary (formulas)
A5: 166683 | B5: Massachusetts Institute of Technology | C5: Cambridge | D5: MA | E5: Private | F5: 20111 | G5: 143372 | H5: =COUNTIF($G$5:$G$1531,">"&G5)+1 | I5: MIT | J5: =IF(E5="Private",F5,"") | K5: =IF(E5="Private",G5,"") | M5: Institutions in file after filters | N5: =COUNTA(B5:B1531)
A6: 115409 | B6: Harvey Mudd College | C6: Claremont | D6: CA | E6: Private | F6: 35924 | G6: 138687 | H6: =COUNTIF($G$5:$G$1531,">"&G6)+1 | J6: =IF(E6="Private",F6,"") | K6: =IF(E6="Private",G6,"") | M6: Public | N6: =COUNTIF(E5:E1531,"Public")
A7: 110404 | B7: California Institute of Technology | C7: Pasadena | D7: CA | E7: Private | F7: 16075 | G7: 128566 | H7: =COUNTIF($G$5:$G$1531,">"&G7)+1 | J7: =IF(E7="Private",F7,"") | K7: =IF(E7="Private",G7,"") | M7: Private | N7: =COUNTIF(E5:E1531,"Private")
A8: 243744 | B8: Stanford University | C8: Stanford | D8: CA | E8: Private | F8: 13807 | G8: 124080 | H8: =COUNTIF($G$5:$G$1531,">"&G8)+1 | J8: =IF(E8="Private",F8,"") | K8: =IF(E8="Private",G8,"") | M8: Northeastern rank | N8: =INDEX(H5:H1531,MATCH("Northeastern University",B5:B1531,0))
A9: 164739 | B9: Bentley University | C9: Waltham | D9: MA | E9: Private | F9: 37930 | G9: 120959 | H9: =COUNTIF($G$5:$G$1531,">"&G9)+1 | J9: =IF(E9="Private",F9,"") | K9: =IF(E9="Private",G9,"") | M9: Vanderbilt rank | N9: =INDEX(H5:H1531,MATCH("Vanderbilt University",B5:B1531,0))
A10: 211440 | B10: Carnegie Mellon University | C10: Pittsburgh | D10: PA | E10: Private | F10: 31944 | G10: 114862 | H10: =COUNTIF($G$5:$G$1531,">"&G10)+1 | J10: =IF(E10="Private",F10,"") | K10: =IF(E10="Private",G10,"") | M10: Boston University rank | N10: =INDEX(H5:H1531,MATCH("Boston University",B5:B1531,0))
A11: 215062 | B11: University of Pennsylvania | C11: Philadelphia | D11: PA | E11: Private | F11: 28699 | G11: 111371 | H11: =COUNTIF($G$5:$G$1531,">"&G11)+1 | J11: =IF(E11="Private",F11,"") | K11: =IF(E11="Private",G11,"") | M11: MIT rank | N11: =INDEX(H5:H1531,MATCH("Massachusetts Institute of Technology",B5:B1531,0))
A12: 186131 | B12: Princeton University | C12: Princeton | D12: NJ | E12: Private | F12: 6128 | G12: 110066 | H12: =COUNTIF($G$5:$G$1531,">"&G12)+1 | J12: =IF(E12="Private",F12,"") | K12: =IF(E12="Private",G12,"") | M12: Private trendline slope | N12: =SLOPE(K5:K1531,J5:J1531)
A13: 122931 | B13: Santa Clara University | C13: Santa Clara | D13: CA | E13: Private | F13: 50062 | G13: 109183 | H13: =COUNTIF($G$5:$G$1531,">"&G13)+1 | J13: =IF(E13="Private",F13,"") | K13: =IF(E13="Private",G13,"") | M13: Private trendline intercept | N13: =INTERCEPT(K5:K1531,J5:J1531)
A14: 186867 | B14: Stevens Institute of Technology | C14: Hoboken | D14: NJ | E14: Private | F14: 41346 | G14: 108772 | H14: =COUNTIF($G$5:$G$1531,">"&G14)+1 | J14: =IF(E14="Private",F14,"") | K14: =IF(E14="Private",G14,"") | M14: Private trendline r | N14: =CORREL(J5:J1531,K5:K1531)
A15: 213543 | B15: Lehigh University | C15: Bethlehem | D15: PA | E15: Private | F15: 36931 | G15: 105584 | H15: =COUNTIF($G$5:$G$1531,">"&G15)+1 | J15: =IF(E15="Private",F15,"") | K15: =IF(E15="Private",G15,"") | M15: Private trendline R-squared | N15: =RSQ(K5:K1531,J5:J1531)
A16: 112260 | B16: Claremont McKenna College | C16: Claremont | D16: CA | E16: Private | F16: 28849 | G16: 104736 | H16: =COUNTIF($G$5:$G$1531,">"&G16)+1 | J16: =IF(E16="Private",F16,"") | K16: =IF(E16="Private",G16,"") | M16: Northeastern earnings | N16: =INDEX(G5:G1531,MATCH("Northeastern University",B5:B1531,0))
A17: 190415 | B17: Cornell University | C17: Ithaca | D17: NY | E17: Private | F17: 28690 | G17: 104043 | H17: =COUNTIF($G$5:$G$1531,">"&G17)+1 | J17: =IF(E17="Private",F17,"") | K17: =IF(E17="Private",G17,"") | M17: Northeastern net price | N17: =INDEX(F5:F1531,MATCH("Northeastern University",B5:B1531,0))
A18: 164924 | B18: Boston College | C18: Chestnut Hill | D18: MA | E18: Private | F18: 41704 | G18: 103937 | H18: =COUNTIF($G$5:$G$1531,">"&G18)+1 | J18: =IF(E18="Private",F18,"") | K18: =IF(E18="Private",G18,"") | M18: Northeastern vs private trendline ($) | N18: =N16-(N13+N12*N17)
A19: 131496 | B19: Georgetown University | C19: Washington | D19: DC | E19: Private | F19: 40815 | G19: 103494 | H19: =COUNTIF($G$5:$G$1531,">"&G19)+1 | J19: =IF(E19="Private",F19,"") | K19: =IF(E19="Private",G19,"")
A20: 168421 | B20: Worcester Polytechnic Institute | C20: Worcester | D20: MA | E20: Private | F20: 43071 | G20: 103470 | H20: =COUNTIF($G$5:$G$1531,">"&G20)+1 | J20: =IF(E20="Private",F20,"") | K20: =IF(E20="Private",G20,"")
A21: 139755 | B21: Georgia Institute of Technology-Main Campus | C21: Atlanta | D21: GA | E21: Public | F21: 12116 | G21: 102772 | H21: =COUNTIF($G$5:$G$1531,">"&G21)+1 | J21: =IF(E21="Private",F21,"") | K21: =IF(E21="Private",G21,"") | M21: Prior release (Oct 10, 2023; 1,557 institutions), for reference
A22: 190150 | B22: Columbia University in the City of New York | C22: New York | D22: NY | E22: Private | F22: 21590 | G22: 102491 | H22: =COUNTIF($G$5:$G$1531,">"&G22)+1 | J22: =IF(E22="Private",F22,"") | K22: =IF(E22="Private",G22,"") | M22: Northeastern rank / earnings / net price | N22: 38th; $88,842; $34,255
A23: 194824 | B23: Rensselaer Polytechnic Institute | C23: Troy | D23: NY | E23: Private | F23: 36228 | G23: 102051 | H23: =COUNTIF($G$5:$G$1531,">"&G23)+1 | J23: =IF(E23="Private",F23,"") | K23: =IF(E23="Private",G23,"") | M23: Vanderbilt rank | N23: 53rd ($84,415)
A24: 166027 | B24: Harvard University | C24: Cambridge | D24: MA | E24: Private | F24: 19066 | G24: 101817 | H24: =COUNTIF($G$5:$G$1531,">"&G24)+1 | J24: =IF(E24="Private",F24,"") | K24: =IF(E24="Private",G24,"") | M24: Boston University rank | N24: 75th ($80,582)
A25: 130794 | B25: Yale University | C25: New Haven | D25: CT | E25: Private | F25: 23777 | G25: 100533 | H25: =COUNTIF($G$5:$G$1531,">"&G25)+1 | J25: =IF(E25="Private",F25,"") | K25: =IF(E25="Private",G25,"") | M25: MIT rank / net price | N25: 2nd; $5,084 net price
A26: 216597 | B26: Villanova University | C26: Villanova | D26: PA | E26: Private | F26: 43756 | G26: 100423 | H26: =COUNTIF($G$5:$G$1531,">"&G26)+1 | J26: =IF(E26="Private",F26,"") | K26: =IF(E26="Private",G26,"") | M26: Private trendline | N26: slope 1.035, intercept $29,753, r 0.49
A27: 152080 | B27: University of Notre Dame | C27: Notre Dame | D27: IN | E27: Private | F27: 26780 | G27: 99980 | H27: =COUNTIF($G$5:$G$1531,">"&G27)+1 | J27: =IF(E27="Private",F27,"") | K27: =IF(E27="Private",G27,"")
A28: 198419 | B28: Duke University | C28: Durham | D28: NC | E28: Private | F28: 29612 | G28: 97800 | H28: =COUNTIF($G$5:$G$1531,">"&G28)+1 | J28: =IF(E28="Private",F28,"") | K28: =IF(E28="Private",G28,"")
A29: 182670 | B29: Dartmouth College | C29: Hanover | D29: NH | E29: Private | F29: 29519 | G29: 97434 | H29: =COUNTIF($G$5:$G$1531,">"&G29)+1 | J29: =IF(E29="Private",F29,"") | K29: =IF(E29="Private",G29,"")
A30: 126775 | B30: Colorado School of Mines | C30: Golden | D30: CO | E30: Public | F30: 28690 | G30: 97335 | H30: =COUNTIF($G$5:$G$1531,">"&G30)+1 | J30: =IF(E30="Private",F30,"") | K30: =IF(E30="Private",G30,"")
A31: 196291 | B31: SUNY Maritime College | C31: Throggs Neck | D31: NY | E31: Public | F31: 22367 | G31: 95951 | H31: =COUNTIF($G$5:$G$1531,">"&G31)+1 | J31: =IF(E31="Private",F31,"") | K31: =IF(E31="Private",G31,"")
A32: 169983 | B32: Kettering University | C32: Flint | D32: MI | E32: Private | F32: 34660 | G32: 94823 | H32: =COUNTIF($G$5:$G$1531,">"&G32)+1 | J32: =IF(E32="Private",F32,"") | K32: =IF(E32="Private",G32,"")
A33: 234207 | B33: Washington and Lee University | C33: Lexington | D33: VA | E33: Private | F33: 23781 | G33: 94810 | H33: =COUNTIF($G$5:$G$1531,">"&G33)+1 | J33: =IF(E33="Private",F33,"") | K33: =IF(E33="Private",G33,"")
A34: 111188 | B34: Cal Poly Maritime Academy | C34: Vallejo | D34: CA | E34: Public | F34: 20555 | G34: 94784 | H34: =COUNTIF($G$5:$G$1531,">"&G34)+1 | J34: =IF(E34="Private",F34,"") | K34: =IF(E34="Private",G34,"")
A35: 211291 | B35: Bucknell University | C35: Lewisburg | D35: PA | E35: Private | F35: 40766 | G35: 93807 | H35: =COUNTIF($G$5:$G$1531,">"&G35)+1 | J35: =IF(E35="Private",F35,"") | K35: =IF(E35="Private",G35,"")
A36: 217156 | B36: Brown University | C36: Providence | D36: RI | E36: Private | F36: 25184 | G36: 93487 | H36: =COUNTIF($G$5:$G$1531,">"&G36)+1 | J36: =IF(E36="Private",F36,"") | K36: =IF(E36="Private",G36,"")
A37: 167358 | B37: Northeastern University | C37: Boston | D37: MA | E37: Private | F37: 30915 | G37: 92538 | H37: =COUNTIF($G$5:$G$1531,">"&G37)+1 | I37: Northeastern | J37: =IF(E37="Private",F37,"") | K37: =IF(E37="Private",G37,"")
A38: 118888 | B38: Northeastern University Oakland | C38: Oakland | D38: CA | E38: Private | F38: 25181 | G38: 92538 | H38: =COUNTIF($G$5:$G$1531,">"&G38)+1 | J38: =IF(E38="Private",F38,"") | K38: =IF(E38="Private",G38,"")
A39: 123961 | B39: University of Southern California | C39: Los Angeles | D39: CA | E39: Private | F39: 32740 | G39: 92498 | H39: =COUNTIF($G$5:$G$1531,">"&G39)+1 | J39: =IF(E39="Private",F39,"") | K39: =IF(E39="Private",G39,"")
A40: 110635 | B40: University of California-Berkeley | C40: Berkeley | D40: CA | E40: Public | F40: 13481 | G40: 92446 | H40: =COUNTIF($G$5:$G$1531,">"&G40)+1 | J40: =IF(E40="Private",F40,"") | K40: =IF(E40="Private",G40,"")
A41: 144050 | B41: University of Chicago | C41: Chicago | D41: IL | E41: Private | F41: 14860 | G41: 91885 | H41: =COUNTIF($G$5:$G$1531,">"&G41)+1 | J41: =IF(E41="Private",F41,"") | K41: =IF(E41="Private",G41,"")
...

Sheet S2_Survey
A1: Slide 2: 'Faculty / Trustees / Sr. administrators are aware of and understand the financial challenges confronting my institution'
A2: % of business officers answering 4 or 5 on a five-point scale, all institutions. Verified against each report; original slide values shown for comparison.
A4: Survey year | B4: Faculty | C4: Trustees | D4: Sr. Administrators | E4: Trustees minus Faculty (pts) | F4: Sr. Admin minus Faculty (pts) | G4: Original slide: Faculty | H4: Original slide: Trustees | I4: Original slide: Sr. Admin | J4: Differs from original? | K4: Item type | L4: n respondents | M4: Source (report page / table)
A5: 2015 | B5: 0.32 | C5: 0.79 | D5: 0.88 | E5: =(C5-B5)*100 | F5: =(D5-B5)*100 | G5: 0.33 | H5: 0.79 | I5: 0.88 | J5: =IF(AND(B5=G5,C5=H5,D5=I5),"same","DIFFERS") | K5: aware of and understand | L5: 403 | M5: Detail table 13 (PDF/printed pp.27-29): senior admins p.27, trustees p.28, faculty p.29. Narrative p.27 and 'Snapshot of findings' p.7. Infographic on p.9 (chart). | https://www.insidehighered.com/news/survey/closure-concerns-and-financial-strategies-survey-college-business-officers
A6: 2016 | B6: 0.27 | C6: 0.74 | D6: 0.86 | E6: =(C6-B6)*100 | F6: =(D6-B6)*100 | G6: 0.27 | H6: 0.74 | I6: 0.86 | J6: =IF(AND(B6=G6,C6=H6,D6=I6),"same","DIFFERS") | K6: faculty item worded differently | L6: 386 | M6: Senior admins and trustees: table on p.18 (narrative p.17). Faculty: table on p.20 (narrative p.19), and a split table p.21 by whether faculty play a meaningful budget role. | https://www.insidehighered.com/news/survey/foundering-finances-faculty-role-survey-business-officers
A7: 2017 | B7: 0.32 | C7: 0.77 | D7: 0.85 | E7: =(C7-B7)*100 | F7: =(D7-B7)*100 | G7: 0.32 | H7: 0.77 | I7: 0.85 | J7: =IF(AND(B7=G7,C7=H7,D7=I7),"same","DIFFERS") | K7: faculty item worded differently | L7: 409 | M7: Senior admins and trustees: table p.13 (narrative p.12). Faculty: table p.20 (narrative p.19). | https://www.insidehighered.com/news/survey/rose-colored-glasses-come-survey-business-officers
A8: 2018 | B8: 0.44 | C8: 0.78 | D8: 0.8 | E8: =(C8-B8)*100 | F8: =(D8-B8)*100 | G8: 0.44 | H8: 0.78 | I8: 0.8 | J8: =IF(AND(B8=G8,C8=H8,D8=I8),"same","DIFFERS") | K8: aware of and understand | L8: 415 | M8: Tables on p.30 (senior admins), p.31 (trustees), p.32 (faculty); narrative p.29. | https://www.insidehighered.com/news/survey/peril-private-colleges-survey-business-officers
A9: 2019 | B9: 0.32 | C9: 0.78 | D9: 0.9 | E9: =(C9-B9)*100 | F9: =(D9-B9)*100 | G9: 0.32 | H9: 0.78 | I9: 0.9 | J9: =IF(AND(B9=G9,C9=H9,D9=I9),"same","DIFFERS") | K9: aware of and understand | L9: 416 | M9: Chart-tables on p.14 (trustees, senior admins) and p.15 (faculty); narrative p.13. Read visually from rendered PNGs because pdftotext scrambles the chevron chart labels. | https://www.insidehighered.com/news/survey/challenges-regional-publics-survey-business-officers
A10: 2020 | B10: 0.34 | C10: 0.84 | D10: 0.9 | E10: =(C10-B10)*100 | F10: =(D10-B10)*100 | G10: 0.31 | H10: 0.87 | I10: 0.93 | J10: =IF(AND(B10=G10,C10=H10,D10=I10),"same","DIFFERS") | K10: aware of and understand | L10: 273 | M10: Chart-tables on p.19 (trustees, senior admins; narrative also p.19) and p.20 (faculty). Read visually from rendered PNGs. | https://www.insidehighered.com/news/survey/covid-19s-forceful-financial-hit-survey-business-officers
A11: 2021 | B11: 0.5 | C11: 0.85 | D11: 0.9 | E11: =(C11-B11)*100 | F11: =(D11-B11)*100 | G11: 0.5 | H11: 0.85 | I11: 0.9 | J11: =IF(AND(B11=G11,C11=H11,D11=I11),"same","DIFFERS") | K11: aware of and understand | L11: 133 | M11: Stacked-bar chart p.27 (rendered and read); appendix detail tables pp.49-50 ('All' column). | https://www.insidehighered.com/news/survey/college-business-officers-surprisingly-upbeat-about-their-finances
A12: 2022 | B12: 0.53 | C12: 0.9 | D12: 0.91 | E12: =(C12-B12)*100 | F12: =(D12-B12)*100 | G12: 0.28 | H12: 0.91 | I12: 0.91 | J12: =IF(AND(B12=G12,C12=H12,D12=I12),"same","DIFFERS") | K12: aware of and understand | L12: 238 | M12: PDF p.47 (faculty table) and p.48 (senior admin and trustees tables) = source of the values above; p.28 'Financial Management' chart (misaligned, see notes); p.3 methodology | https://www.insidehighered.com/news/survey/college-business-officers-upbeat-despite-worrisome-outlook
A13: 2023 | B13: 0.45 | C13: 0.86 | D13: 0.91 | E13: =(C13-B13)*100 | F13: =(D13-B13)*100 | G13: 0.45 | H13: 0.86 | I13: 0.91 | J13: =IF(AND(B13=G13,C13=H13,D13=I13),"same","DIFFERS") | K13: aware of and understand | L13: 217 | M13: PDF p.19 'Institutional Change: Governance and Mindset' (narrative + chart); p.47 (faculty table); p.48 (senior admin and trustees tables); p.3 methodology | https://www.insidehighered.com/reports/2023/07/12/2023-survey-college-and-university-business-officers
A14: 2024 | B14: 0.39 | C14: 0.79 | D14: 0.88 | E14: =(C14-B14)*100 | F14: =(D14-B14)*100 | G14: 0.44 | H14: 0.91 | I14: 0.95 | J14: =IF(AND(B14=G14,C14=H14,D14=I14),"same","DIFFERS") | K14: aware of and understand | L14: 224 | M14: PDF p.34 'Financial Responsibility: Responsiveness and Mindset' (narrative + chart); p.58 (faculty table); p.60 (senior admin and trustees tables); p.5 methodology | https://www.insidehighered.com/reports/2024/07/16/2024-survey-college-and-university-chief-business-officers
A15: 2025 | C15: 0.74 | K15: trustees-only item | L15: 169 | M15: PDF p.27 'Leadership and Governance: Agency, Shared Governance and Political Interference'; p.59 Detailed Tables; p.3 methodology | https://www.insidehighered.com/reports/2025/07/17/2025-survey-college-and-university-chief-business-officers
A16: 2026 | C16: 0.79 | K16: trustees-only item | L16: 213 | M16: PDF p.33 'Leadership and Governance: On the Job'; p.6 Key Findings; p.62 Detailed Tables; p.3 methodology | https://www.insidehighered.com/reports/2026/07/15/2026-survey-college-and-university-chief-business-officers
A18: 2014 was removed from the slide as requested (report wording then: 'realistic about'; Faculty 22%, Trustees 67%, Sr. Admin 75%).
A19: 2025-2026: only a trustees-only statement was asked ('Trustees understand the financial challenges confronting my institution'); it is not the same series.
A21: Rows differing from the original slide | E21: =COUNTIF(J5:J16,"DIFFERS")

Sheet S3_FY25
A1: Slide 3: FY25 salaries & wages per student (audited financial statements; see Evidence)
A2: Core operating expenses = total operating expenses - depreciation - amortization - interest. S&W basis: audited line, Form 990 / MD&A chart, or ESTIMATE (Penn, Stanford: 35% assumed fringe rate). Students = fall 2024 total enrollment.
A3: Assumed fringe benefit rate (benefits / S&W) for Penn and Stanford | E3: 0.35 | F3: <- input: S&W = combined salaries + benefits / (1 + rate). Change it and the estimates, slide-3 inputs and sensitivities update here.
A4: Institution | B4: Fiscal year end | C4: Salaries & wages ($) | D4: S&W basis | E4: Salaries + benefits, combined ($) | F4: Form 990 S&W ($) | G4: Form 990 lines 5-10 ($) | H4: Total operating expenses ($) | I4: Depreciation ($) | J4: Amortization ($) | K4: Interest ($) | L4: Core operating expenses ($) | M4: Students (fall 2024) | N4: S&W per student | O4: Core opex per student (x) | P4: S&W share of core opex (y) | Q4: Check: x*y - S&W/student | R4: Health system consolidated | S4: Notes
A5: Rice | B5: June 30, 2025 | C5: 515800000 | D5: audited line | E5: =C5+123330000 | H5: 1087937000 | I5: 82255000 | K5: 45396000 | L5: =H5-I5-J5-K5 | M5: 8961 | N5: =C5/M5 | O5: =L5/M5 | P5: =C5/L5 | Q5: =O5*P5-N5 | R5: no | S5: Depreciation and amortization are one line; interest and bond costs separate.
A6: Vanderbilt | B6: June 30, 2025 | C6: 804000000 | D6: MD&A expense chart | E6: 976417000 | H6: 1799663000 | I6: 116913000 | K6: 30063000 | L6: =H6-I6-J6-K6 | M6: 13575 | N6: =C6/M6 | O6: =L6/M6 | P6: =C6/L6 | Q6: =O6*P6-N6 | R6: no | S6: Audited statements show salaries, wages and benefits combined ($976.4M). S&W from the MD&A expense chart ($M precision). VUMC is not consolidated.
A7: Northwestern | B7: August 31, 2025 | C7: =F7 | D7: Form 990 (ties to audited) | E7: 1997951000 | F7: 1556522638 | G7: 1997950859 | H7: 3607255000 | I7: 216713000 | K7: 99478000 | L7: =H7-I7-J7-K7 | M7: 23431 | N7: =C7/M7 | O7: =L7/M7 | P7: =C7/L7 | Q7: =O7*P7-N7 | R7: no | S7: Audited statements show salaries, wages and benefits combined. Form 990 lines 5-10 tie to that line to the dollar, so 990 S&W is on the audited basis.
A8: Princeton | B8: June 30, 2025 | C8: 1162823000 | D8: audited line | E8: =C8+351760000 | H8: 2744548000 | I8: 231467000 | K8: 221826000 | L8: =H8-I8-J8-K8 | M8: 9050 | N8: =C8/M8 | O8: =L8/M8 | P8: =C8/L8 | Q8: =O8*P8-N8 | R8: no | S8: Includes the Plasma Physics Laboratory ($246.9M expense). Students from the Report of the Treasurer (CDS host not reachable).
A9: Harvard | B9: June 30, 2025 | D9: pending | M9: 21189 | S9: PENDING: Harvard's finance site denies automated access; FY25 Financial Report PDF needed.
A10: Yale | B10: June 30, 2025 | C10: 2737371000 | D10: audited line | E10: =C10+861635000 | H10: 5807911000 | I10: 504923000 | L10: =H10-I10-J10-K10 | M10: 15564 | N10: =C10/M10 | O10: =L10/M10 | P10: =C10/L10 | Q10: =O10*P10-N10 | R10: no | S10: Yale reports depreciation, amortization and interest as ONE operating line ($504.9M); shown in the depreciation column.
A11: Chicago | B11: June 30, 2025 | C11: 3678678000 | D11: audited line | E11: 4517817000 | H11: 8283042000 | I11: 401386000 | K11: 215170000 | L11: =H11-I11-J11-K11 | M11: 16221 | N11: =C11/M11 | O11: =L11/M11 | P11: =C11/L11 | Q11: =O11*P11-N11 | R11: UChicago Medicine | S11: Includes UChicago Medicine; Argonne and Fermilab are not consolidated.
A12: Duke | B12: June 30, 2025 | C12: 5041664000 | D12: audited line | E12: 6230712000 | H12: 10953208000 | I12: 471677000 | K12: 161512000 | L12: =H12-I12-J12-K12 | M12: 17499 | N12: =C12/M12 | O12: =L12/M12 | P12: =C12/L12 | Q12: =O12*P12-N12 | R12: Duke University Health System | S12: Depreciation and amortization are one line ($471.7M). Health system acquired the physician practice July 1, 2023 (FY23 not comparable; FY25 fine).
A13: Emory | B13: August 31, 2025 | C13: 5265449000 | D13: audited line | E13: =C13+1259151000 | H13: 10577959000 | I13: 379158000 | K13: 113892000 | L13: =H13-I13-J13-K13 | M13: 15179 | N13: =C13/M13 | O13: =L13/M13 | P13: =C13/L13 | Q13: =O13*P13-N13 | R13: Emory Healthcare | S13: Depreciation and amortization are one line ($379.2M).
A14: Penn | B14: June 30, 2025 | C14: =E14/(1+$E$3) | D14: ESTIMATE (combined / (1 + fringe rate)) | E14: 9019270000 | F14: 4515553000 | G14: 5886033000 | H14: 16445321000 | I14: 686510000 | K14: 133923000 | L14: =H14-I14-J14-K14 | M14: 24023 | N14: =C14/M14 | O14: =L14/M14 | P14: =C14/L14 | Q14: =O14*P14-N14 | R14: Penn Medicine (UPHS) | S14: Statements show 'compensation and benefits' combined only. S&W ESTIMATED = combined / (1 + 35% assumed fringe rate), per Northeastern. Columns F-G (Form 990, narrower scope) are shown for reference only. D&A one line.
A15: Stanford | B15: August 31, 2025 | C15: =E15/(1+$E$3) | D15: ESTIMATE (combined / (1 + fringe rate)) | E15: 11647045000 | F15: 4781181437 | G15: 5963697901 | H15: 18935447000 | I15: 930917000 | K15: 278763000 | L15: =H15-I15-J15-K15 | M15: 18625 | N15: =C15/M15 | O15: =L15/M15 | P15: =C15/L15 | Q15: =O15*P15-N15 | R15: Stanford Health Care and Lucile Packard Children's Hospital | S15: Statements show salaries and benefits combined only. S&W ESTIMATED = combined / (1 + 35% assumed fringe rate), per Northeastern. Columns F-G (Form 990, narrower scope) are reference only. Interest is net and embedded in other operating expenses. Includes SLAC and the hospitals.
A16: Northeastern | B16: June 30, 2025 | C16: =F16 | D16: Form 990 (96.8% of audited combined) | E16: 1341049000 | F16: 1045135178 | G16: 1297581752 | H16: 2388249000 | I16: 151250000 | K16: 49862000 | L16: =H16-I16-J16-K16 | M16: 39774 | N16: =C16/M16 | O16: =L16/M16 | P16: =C16/L16 | Q16: =O16*P16-N16 | R16: no | S16: Audited statements show 'Salary and benefits' combined ($1,341.0M). S&W from Form 990 lines 5+6+7 (990 lines 5-10 are 96.8% of the audited combined line). Interest ($49.9M) is below the debt-note figure ($60.0M).
A17: Boston University | B17: June 30, 2025 | C17: 1238476000 | D17: audited line | E17: =C17+389796000 | H17: 2719848000 | I17: 160697000 | K17: 81689000 | L17: =H17-I17-J17-K17 | M17: 37737 | N17: =C17/M17 | O17: =L17/M17 | P17: =C17/L17 | Q17: =O17*P17-N17 | R17: no | S17: Separate S&W line in the audited statements. Boston Medical Center is not consolidated. Right-of-use amortization (~$15M) not removed.
A18: MIT | B18: June 30, 2025 | C18: 2090862000 | D18: audited line | E18: 2796822000 | H18: 5117184000 | I18: 289575000 | K18: 170489000 | L18: =H18-I18-J18-K18 | M18: 11886 | N18: =C18/M18 | O18: =L18/M18 | P18: =C18/L18 | Q18: =O18*P18-N18 | R18: no | S18: Includes Lincoln Laboratory (S&W not disclosed separately). 'Total expenses before depreciation and interest' = core. Net periodic benefit income of $170M is outside operating expenses.
A20: Median (13 schools with data) | N20: =MEDIAN(N5:N18) | O20: =MEDIAN(O5:O18) | P20: =MEDIAN(P5:P18)
A21: Northeastern rank, S&W per student (1 = lowest) | N21: =RANK(N16,N5:N18,1)
A22: Northeastern S&W per student as % of peer median | N22: =N16/N20

Sheet S3_Sensitivity
A1: Slide 3: sensitivity of the conclusions to the three judgement calls
A2: A: student count basis for Northeastern. B: all schools, CDS fall 2024 vs IPEDS-style headcount. C: estimated S&W for Penn and Stanford under alternative wage shares.
A4: A. Northeastern S&W per student by student-count basis
A5: Basis | B5: Students | C5: S&W per student | D5: Core opex per student | E5: Note
A6: Common Data Set 2024-25 (used on slide) | B6: 39774 | C6: =S3_FY25!C16/B6 | D6: =S3_FY25!L16/B6 | E6: B1 'total all students'
A7: IPEDS-style headcount (College Navigator fall 2024) | B7: 32553 | C7: =S3_FY25!C16/B7 | D7: =S3_FY25!L16/B7 | E7: As reported by the enrollment agent from College Navigator; IPEDS file for fall 2024 is not yet posted
A8: Northeastern Facts and Figures fall 2024 | B8: 48812 | C8: =S3_FY25!C16/B8 | D8: =S3_FY25!L16/B8 | E8: Excludes non-degree students; adds co-op students as an extra column
A10: B. S&W per student: CDS fall 2024 vs IPEDS fall 2023 headcount
A11: Institution | B11: CDS fall 2024 | C11: IPEDS fall 2023 | D11: S&W per student (CDS) | E11: S&W per student (IPEDS F23) | F11: Rank low-to-high (CDS) | G11: Rank low-to-high (IPEDS) | H11: IPEDS F23 vs CDS F24 (%)
A12: Rice | B12: =S3_FY25!M5 | C12: 8556 | D12: =S3_FY25!C5/B12 | E12: =S3_FY25!C5/C12 | F12: =RANK(D12,D$12:D$24,1) | G12: =RANK(E12,E$12:E$24,1) | H12: =(C12/B12-1)*100
A13: Vanderbilt | B13: =S3_FY25!M6 | C13: 13456 | D13: =S3_FY25!C6/B13 | E13: =S3_FY25!C6/C13 | F13: =RANK(D13,D$12:D$24,1) | G13: =RANK(E13,E$12:E$24,1) | H13: =(C13/B13-1)*100
A14: Northwestern | B14: =S3_FY25!M7 | C14: 23203 | D14: =S3_FY25!C7/B14 | E14: =S3_FY25!C7/C14 | F14: =RANK(D14,D$12:D$24,1) | G14: =RANK(E14,E$12:E$24,1) | H14: =(C14/B14-1)*100
A15: Princeton | B15: =S3_FY25!M8 | C15: 8922 | D15: =S3_FY25!C8/B15 | E15: =S3_FY25!C8/C15 | F15: =RANK(D15,D$12:D$24,1) | G15: =RANK(E15,E$12:E$24,1) | H15: =(C15/B15-1)*100
A16: Yale | B16: =S3_FY25!M10 | C16: 15081 | D16: =S3_FY25!C10/B16 | E16: =S3_FY25!C10/C16 | F16: =RANK(D16,D$12:D$24,1) | G16: =RANK(E16,E$12:E$24,1) | H16: =(C16/B16-1)*100
A17: Chicago | B17: =S3_FY25!M11 | C17: 18339 | D17: =S3_FY25!C11/B17 | E17: =S3_FY25!C11/C17 | F17: =RANK(D17,D$12:D$24,1) | G17: =RANK(E17,E$12:E$24,1) | H17: =(C17/B17-1)*100
A18: Duke | B18: =S3_FY25!M12 | C18: 17112 | D18: =S3_FY25!C12/B18 | E18: =S3_FY25!C12/C18 | F18: =RANK(D18,D$12:D$24,1) | G18: =RANK(E18,E$12:E$24,1) | H18: =(C18/B18-1)*100
A19: Emory | B19: =S3_FY25!M13 | C19: 15046 | D19: =S3_FY25!C13/B19 | E19: =S3_FY25!C13/C19 | F19: =RANK(D19,D$12:D$24,1) | G19: =RANK(E19,E$12:E$24,1) | H19: =(C19/B19-1)*100
A20: Penn | B20: =S3_FY25!M14 | C20: 28711 | D20: =S3_FY25!C14/B20 | E20: =S3_FY25!C14/C20 | F20: =RANK(D20,D$12:D$24,1) | G20: =RANK(E20,E$12:E$24,1) | H20: =(C20/B20-1)*100
A21: Stanford | B21: =S3_FY25!M15 | C21: 18446 | D21: =S3_FY25!C15/B21 | E21: =S3_FY25!C15/C21 | F21: =RANK(D21,D$12:D$24,1) | G21: =RANK(E21,E$12:E$24,1) | H21: =(C21/B21-1)*100
A22: Northeastern | B22: =S3_FY25!M16 | C22: 31159 | D22: =S3_FY25!C16/B22 | E22: =S3_FY25!C16/C22 | F22: =RANK(D22,D$12:D$24,1) | G22: =RANK(E22,E$12:E$24,1) | H22: =(C22/B22-1)*100
A23: Boston University | B23: =S3_FY25!M17 | C23: 36624 | D23: =S3_FY25!C17/B23 | E23: =S3_FY25!C17/C23 | F23: =RANK(D23,D$12:D$24,1) | G23: =RANK(E23,E$12:E$24,1) | H23: =(C23/B23-1)*100
A24: MIT | B24: =S3_FY25!M18 | C24: 11920 | D24: =S3_FY25!C18/B24 | E24: =S3_FY25!C18/C24 | F24: =RANK(D24,D$12:D$24,1) | G24: =RANK(E24,E$12:E$24,1) | H24: =(C24/B24-1)*100
A27: C. Penn and Stanford estimated S&W under alternative assumptions
A28: Institution | B28: Salaries + benefits ($) | C28: Fringe rate used (input on S3_FY25) | D28: S&W per student, used | E28: Alt 1: own Form 990 S&W share | F28: S&W per student, Alt 1 | G28: Alt 1 vs used (%) | H28: Alt 2: original slide 72.8% | I28: S&W per student, Alt 2 | J28: Alt 2 vs used (%)
A29: Penn | B29: =S3_FY25!E14 | C29: =S3_FY25!E3 | D29: =B29/(1+C29)/S3_FY25!M14 | E29: =S3_FY25!F14/S3_FY25!G14 | F29: =B29*E29/S3_FY25!M14 | G29: =(F29/D29-1)*100 | H29: 0.728 | I29: =B29*H29/S3_FY25!M14 | J29: =(I29/D29-1)*100
A30: Stanford | B30: =S3_FY25!E15 | C30: =S3_FY25!E3 | D30: =B30/(1+C30)/S3_FY25!M15 | E30: =S3_FY25!F15/S3_FY25!G15 | F30: =B30*E30/S3_FY25!M15 | G30: =(F30/D30-1)*100 | H30: 0.728 | I30: =B30*H30/S3_FY25!M15 | J30: =(I30/D30-1)*100
A32: D. Fringe benefit rates (benefits / S&W) observed where audited statements report both lines
A33: Institution | B33: S&W ($) | C33: Benefits ($) | D33: Fringe rate
A34: Rice | B34: =S3_FY25!C5 | C34: =S3_FY25!E5-S3_FY25!C5 | D34: =C34/B34
A35: Princeton | B35: =S3_FY25!C8 | C35: =S3_FY25!E8-S3_FY25!C8 | D35: =C35/B35
A36: Yale | B36: =S3_FY25!C10 | C36: =S3_FY25!E10-S3_FY25!C10 | D36: =C36/B36
A37: Chicago | B37: =S3_FY25!C11 | C37: =S3_FY25!E11-S3_FY25!C11 | D37: =C37/B37
A38: Duke | B38: =S3_FY25!C12 | C38: =S3_FY25!E12-S3_FY25!C12 | D38: =C38/B38
A39: Emory | B39: =S3_FY25!C13 | C39: =S3_FY25!E13-S3_FY25!C13 | D39: =C39/B39
A40: Boston University | B40: =S3_FY25!C17 | C40: =S3_FY25!E17-S3_FY25!C17 | D40: =C40/B40
A41: MIT | B41: =S3_FY25!C18 | C41: =S3_FY25!E18-S3_FY25!C18 | D41: =C41/B41
A42: Minimum / median / maximum | B42: =MIN(D34:D41) | C42: =MEDIAN(D34:D41) | D42: =MAX(D34:D41)
A43: The 35% assumption sits above every observed rate, so the Penn and Stanford estimates lean low relative to peers (Alt 1 gives higher S&W per student).

Sheet S3_FY23_Recalc
A1: Slide 3: what the original FY23 slide actually used vs the stated definition
A2: Original values from the chart's embedded workbook. Recomputed FY23 from each school's audited statements using the SPEC definition. IPEDS columns: FY23 finance file F2223_F2 fields F2E131 (total expenses) and F2E132 (salaries and wages).
A4: Institution | B4: Original: S&W | C4: Original: 'core opex' | D4: Audited FY23: S&W | E4: Audited FY23: total operating expenses | F4: Audited FY23: depreciation + amortization + interest | G4: Audited FY23: core (total - D&A - interest) | H4: Original 'core' vs audited TOTAL (%) | I4: Original 'core' vs audited CORE (%) | J4: Original S&W vs audited S&W (%) | K4: Audited FY23: salaries + benefits combined | L4: Original S&W / combined | M4: IPEDS FY23 F2E131 (total exp) | N4: IPEDS FY23 F2E132 (S&W)
A5: Rice | B5: 421781000 | C5: 959377000 | D5: 421781000 | E5: 959377000 | F5: 118187000 | G5: =E5-F5 | H5: =(C5/E5-1)*100 | I5: =(C5/G5-1)*100 | J5: =(B5/D5-1)*100 | M5: 959377000 | N5: 421781000
A6: Vanderbilt | B6: 699234000 | C6: 1615854000 | D6: 700000000 | E6: 1615854000 | F6: 122175000 | G6: =E6-F6 | H6: =(C6/E6-1)*100 | I6: =(C6/G6-1)*100 | J6: =(B6/D6-1)*100 | K6: 832612000 | L6: =B6/K6 | M6: 1615854013 | N6: 699234852
A7: Northwestern | B7: 1219645336 | C7: 3038060000 | E7: 3038060000 | F7: 303553000 | G7: =E7-F7 | H7: =(C7/E7-1)*100 | I7: =(C7/G7-1)*100 | K7: 1675337000 | L7: =B7/K7 | M7: 3038060000 | N7: 1334540000
A8: Princeton | B8: 969089000 | C8: 2263259000 | D8: 969089000 | E8: 2263259000 | F8: 349162000 | G8: =E8-F8 | H8: =(C8/E8-1)*100 | I8: =(C8/G8-1)*100 | J8: =(B8/D8-1)*100 | M8: 2263259000 | N8: 886833000
A9: Harvard | B9: 2421076000 | C9: 5911797000 | D9: Harvard FY23 report not reached | M9: 5911797000 | N9: 2421074000
A10: Yale | B10: 2328136000 | C10: 4936268000 | D10: 2328136000 | E10: 4936268000 | F10: 441202000 | G10: =E10-F10 | H10: =(C10/E10-1)*100 | I10: =(C10/G10-1)*100 | J10: =(B10/D10-1)*100 | M10: 4873675887 | N10: 2202260626
A11: Chicago | B11: 3033100000 | C11: 6779655000 | D11: 3033100000 | E11: 6779655000 | F11: 563830000 | G11: =E11-F11 | H11: =(C11/E11-1)*100 | I11: =(C11/G11-1)*100 | J11: =(B11/D11-1)*100 | K11: 3662513000 | L11: =B11/K11 | M11: 5084463771 | N11: 1604106945
A12: Duke | B12: 3676675000 | C12: 8431382000 | D12: 3676675000 | E12: 8431382000 | F12: 635501000 | G12: =E12-F12 | H12: =(C12/E12-1)*100 | I12: =(C12/G12-1)*100 | J12: =(B12/D12-1)*100 | K12: 4568399000 | L12: =B12/K12 | M12: 8431382000 | N12: 3609077000
A13: Emory | B13: 4313737000 | C13: 8570621000 | D13: 4313737000 | E13: 8570621000 | F13: 452316000 | G13: =E13-F13 | H13: =(C13/E13-1)*100 | I13: =(C13/G13-1)*100 | J13: =(B13/D13-1)*100 | M13: 8514754000 | N13: 4252849000
A14: Penn | B14: 5636695792 | C14: 13857148000 | E14: 13857148000 | F14: 789992000 | G14: =E14-F14 | H14: =(C14/E14-1)*100 | I14: =(C14/G14-1)*100 | K14: 7742714000 | L14: =B14/K14 | M14: 13857148000 | N14: 6045218000
A15: Stanford | B15: 7106067696 | C15: 16053362000 | E15: 16053362000 | F15: 1116974000 | G15: =E15-F15 | H15: =(C15/E15-1)*100 | I15: =(C15/G15-1)*100 | K15: 9761082000 | L15: =B15/K15 | M15: 7659884000 | N15: 3467999000
A17: Reading it: column H is ~0% for every school with data: the original 'core operating expenses' equal audited total operating expenses (depreciation and interest were never removed). Column L is exactly 0.7280 for Penn, Stanford and Northwestern: their original S&W was 72.8% of combined salaries and benefits, an undisclosed assumption.

Sheet S3_Enrollment
A1: Slide 3: student counts (Common Data Set B1 'total all students') vs IPEDS vs the original slide
A2: IPEDS fall 2024 is not yet posted, so IPEDS fall 2022 and 2023 are shown for calibration.
A4: Institution | B4: CDS fall 2024 (used) | C4: CDS fall 2023 | D4: CDS fall 2022 | E4: IPEDS fall 2023 | F4: IPEDS fall 2022 | G4: Original slide count (FY23) | H4: IPEDS F23 vs CDS F23 (%) | I4: Original vs IPEDS F22 (%) | J4: Source of fall 2024 count
A5: Rice | B5: 8961 | C5: 8556 | D5: 8672 | E5: 8556 | F5: 8672 | G5: 8285 | H5: =(E5/C5-1)*100 | I5: =(G5/F5-1)*100 | J5: https://ideas.rice.edu/wp-content/uploads/2025/10/CDS_2024-25_WEBSITE.pdf
A6: Vanderbilt | B6: 13575 | C6: 13456 | D6: 13710 | E6: 13456 | F6: 13710 | G6: 13710 | H6: =(E6/C6-1)*100 | I6: =(G6/F6-1)*100 | J6: https://cdn.vanderbilt.edu/vu-wpfsx/wp-content/uploads/sites/70/2025/11/CDS_2024-2025.xlsx
A7: Northwestern | B7: 23431 | C7: 22801 | D7: 22732 | E7: 23203 | F7: 23161 | G7: 23000 | H7: =(E7/C7-1)*100 | I7: =(G7/F7-1)*100 | J7: https://enrollment.northwestern.edu/data/2024-2025.pdf
A8: Princeton | B8: 9050 | E8: 8922 | F8: 8842 | G8: 8778 | I8: =(G8/F8-1)*100 | J8: Princeton Report of the Treasurer FY25: 5,726 undergraduates + 3,324 graduate students (term not named; CDS host not reachable)
A9: Harvard | B9: 21189 | C9: 21278 | D9: 21613 | E9: 30386 | F9: 30631 | G9: 21400 | H9: =(E9/C9-1)*100 | I9: =(G9/F9-1)*100 | J9: https://oira.harvard.edu/files/2025/06/HarvardUniversity_CDS_2024-2025.pdf
A10: Yale | B10: 15564 | C10: 15081 | D10: 14806 | E10: 15081 | F10: 14776 | G10: 14751 | H10: =(E10/C10-1)*100 | I10: =(G10/F10-1)*100 | J10: https://oir.yale.edu/sites/default/files/yale_cds_2024-25_rmd_20250612.pdf
A11: Chicago | B11: 16221 | C11: 15763 | D11: 15946 | E11: 18339 | F11: 18339 | G11: 18058 | H11: =(E11/C11-1)*100 | I11: =(G11/F11-1)*100 | J11: https://bpb-us-w2.wpmucdn.com/voices.uchicago.edu/dist/8/2077/files/2025/08/CDS_2024-2025_to_publish.pdf
A12: Duke | B12: 17499 | C12: 17112 | D12: 18024 | E12: 17112 | F12: 18023 | G12: 18009 | H12: =(E12/C12-1)*100 | I12: =(G12/F12-1)*100 | J12: https://ir.provost.duke.edu/sites/default/files/CDS-2024-25-Final-2.pdf
A13: Emory | B13: 15179 | C13: 15046 | D13: 14852 | E13: 15046 | F13: 14841 | G13: 16000 | H13: =(E13/C13-1)*100 | I13: =(G13/F13-1)*100 | J13: https://provost.emory.edu/planning-administration/_includes/documents/sections/institutional-data/emory-common-data-set-2024-2025.pdf
A14: Penn | B14: 24023 | C14: 23790 | D14: 23374 | E14: 28711 | F14: 28201 | G14: 23374 | H14: =(E14/C14-1)*100 | I14: =(G14/F14-1)*100 | J14: https://upenn.box.com/s/ckv4frz37rzxa4u6bdiv2h4yzykqm4ef
A15: Stanford | B15: 18625 | C15: 18446 | D15: 18283 | E15: 18446 | F15: 18283 | G15: 17529 | H15: =(E15/C15-1)*100 | I15: =(G15/F15-1)*100 | J15: https://drive.google.com/file/d/12MjIqdzzHiECf6hfRlbU3RmmIy14hl1H/view (posted at https://irds.stanford.edu/data-findings/cds)
A16: Northeastern | B16: 39774 | C16: 38760 | D16: 36806 | E16: 31159 | F16: 30013 | H16: =(E16/C16-1)*100 | J16: https://uds.northeastern.edu/wp-content/uploads/2026/03/CDS-2024-25.pdf
A17: Boston University | B17: 37737 | C17: 36624 | D17: 36714 | E17: 36624 | F17: 36714 | H17: =(E17/C17-1)*100 | J17: https://www.bu.edu/asir/files/2025/03/cds-2025.pdf (identical bytes to https://www.bu.edu/asir/files/2026/05/2024-2025-Common-Data-Set.pdf, the file the CDS archive page labels '2024-2025 Common Data Set'; section file: https://www.bu.edu/asir/files/2025/03/cds-2025-b.pdf)
A18: MIT | B18: 11886 | C18: 11920 | D18: 11858 | E18: 11920 | F18: 11858 | H18: =(E18/C18-1)*100 | J18: https://ir.mit.edu/projects/2024-25-common-data-set/
A20: Reading it: Harvard (CDS excludes Extension School), Penn (CDS counts degree-seeking traditional programs only), Chicago (CDS ~12-14% below IPEDS) and Northeastern (CDS ~24% ABOVE IPEDS) do not match IPEDS; the original slide mixed fall 2021 (Rice), fall 2022 (Vanderbilt), degree-seeking counts (Harvard, Penn) and round estimates (Emory 16,000, Northwestern 23,000).

Sheet Evidence
A1: Verbatim source rows and documents for each FY25 figure
A2: Amounts in the evidence text are as printed (usually $ thousands). Page numbers are PDF pages unless noted.
A4: Institution | B4: Item | C4: FY25 value ($) | D4: Evidence (verbatim row, statement, page) | E4: Document
A5: Rice | B5: Salaries and wages | C5: 515800000 | D5: 'Salaries and wages 515,800 - 515,800 466,056' (Consolidated Statements of Activities, operating expenses; $ thousands; columns: without donor restr., with donor restr., 2025 total, 2024 total). FY25 audited statements PDF p6 (printed p.4); also natural/functional note 14, PDF p25 (printed p.23): 'Salaries and wages ... Total 515,800'. | E5: FY25 audited consolidated financial statements (auditor's report dated October 30, 2025): https://rice.app.box.com/index.php?rm=box_download_shared_file&shared_name=kuzehuzf01j84ezzqwg3zlll1qc6fq4n&file_id=f_2033251676859 (Box file 'FY 2025 Audited F; FY24 audited consolidated financial statements (auditor's report dated October 30, 2024): https://budgetandfinance.rice.edu/sites/g/files/bxs3451/files/inline-files/FY24%20Signed%20Financial%20Statement.pdf
A6: Rice | B6: Total operating expenses | C6: 1087937000 | D6: 'Total operating expenses 1,087,937 - 1,087,937 1,053,413' (Statement of Activities, FY25 PDF p6, printed p.4). Natural-classification sum (515,800+123,330+35,543+82,255+45,396+20,755+264,858) = 1,087,937 = face total; note 14 total also 1,087,937 (PDF p25). | E6: FY25 audited consolidated financial statements (auditor's report dated October 30, 2025): https://rice.app.box.com/index.php?rm=box_download_shared_file&shared_name=kuzehuzf01j84ezzqwg3zlll1qc6fq4n&file_id=f_2033251676859 (Box file 'FY 2025 Audited F; FY24 audited consolidated financial statements (auditor's report dated October 30, 2024): https://budgetandfinance.rice.edu/sites/g/files/bxs3451/files/inline-files/FY24%20Signed%20Financial%20Statement.pdf
A7: Rice | B7: Depreciation | C7: 82255000 | D7: 'Depreciation and amortization 82,255 - 82,255 81,932' (Statement of Activities, PDF p6); cash flow 'Depreciation of property and equipment 82,255 81,932' (PDF p7). | E7: FY25 audited consolidated financial statements (auditor's report dated October 30, 2025): https://rice.app.box.com/index.php?rm=box_download_shared_file&shared_name=kuzehuzf01j84ezzqwg3zlll1qc6fq4n&file_id=f_2033251676859 (Box file 'FY 2025 Audited F; FY24 audited consolidated financial statements (auditor's report dated October 30, 2024): https://budgetandfinance.rice.edu/sites/g/files/bxs3451/files/inline-files/FY24%20Signed%20Financial%20Statement.pdf
A8: Rice | B8: Interest | C8: 45396000 | D8: 'Interest and bond costs 45,396 - 45,396 40,922' (Statement of Activities, PDF p6); note: 'Interest and bonds costs of $45,396 and $40,922 were charged to operations in 2025 and 2024, respectively. Interest and bond costs of $4,836 and $3,731 were capitalized' (PDF p21). | E8: FY25 audited consolidated financial statements (auditor's report dated October 30, 2025): https://rice.app.box.com/index.php?rm=box_download_shared_file&shared_name=kuzehuzf01j84ezzqwg3zlll1qc6fq4n&file_id=f_2033251676859 (Box file 'FY 2025 Audited F; FY24 audited consolidated financial statements (auditor's report dated October 30, 2024): https://budgetandfinance.rice.edu/sites/g/files/bxs3451/files/inline-files/FY24%20Signed%20Financial%20Statement.pdf
A9: Vanderbilt | B9: Salaries and wages | C9: 804000000 | D9: NOT on the statements (face and note 15 show only 'Salaries, wages, and benefits 976,417'). The MD&A chart 'Operating Expenses by Type (Fiscal 2025)' (FY25 report PDF p.10, in $ millions) shows 'Faculty salaries and wages, $294, 16%', 'Staff and student salaries and wages, $510, 28%' and 'Fringe benefits, $172, 10%'. 294 + 510 = 804 ($M, rounded); 804 + 172 = 976 ties to the statement. | E9: FY25 Vanderbilt Financial Report (audited consolidated financial statements, FY25 and FY24; includes MD&A): https://cdn.vanderbilt.edu/vu-sub/wp-content/uploads/sites/291/2025/10/01145328/2025_VU_Financial_Report.pdf; FY24 Vanderbilt Financial Report (FY24 and FY23): https://cdn.vanderbilt.edu/vu-sub/wp-content/uploads/sites/291/2024/11/07201434/2024_VU_Financial_Report.pdf
A10: Vanderbilt | B10: Total operating expenses | C10: 1799663000 | D10: 'Total expenses 1,799,663' (thousands), the expenses section before 'Results of operations 217,348', FY25 report PDF p.20. MD&A calls it 'Total operating expenses $1,800' million (p.10). | E10: FY25 Vanderbilt Financial Report (audited consolidated financial statements, FY25 and FY24; includes MD&A): https://cdn.vanderbilt.edu/vu-sub/wp-content/uploads/sites/291/2025/10/01145328/2025_VU_Financial_Report.pdf; FY24 Vanderbilt Financial Report (FY24 and FY23): https://cdn.vanderbilt.edu/vu-sub/wp-content/uploads/sites/291/2024/11/07201434/2024_VU_Financial_Report.pdf
A11: Vanderbilt | B11: Depreciation | C11: 116913000 | D11: 'Depreciation 116,913 107,191' (thousands), separate expense line, FY25 report PDF p.20. | E11: FY25 Vanderbilt Financial Report (audited consolidated financial statements, FY25 and FY24; includes MD&A): https://cdn.vanderbilt.edu/vu-sub/wp-content/uploads/sites/291/2025/10/01145328/2025_VU_Financial_Report.pdf; FY24 Vanderbilt Financial Report (FY24 and FY23): https://cdn.vanderbilt.edu/vu-sub/wp-content/uploads/sites/291/2024/11/07201434/2024_VU_Financial_Report.pdf
A12: Vanderbilt | B12: Interest | C12: 30063000 | D12: 'Interest expense 30,063' (thousands), separate expense line, FY25 report PDF p.20; note (p.33): 'Interest expense of $30.1 million in fiscal 2025 is net of capitalized interest of $5.4 million.' | E12: FY25 Vanderbilt Financial Report (audited consolidated financial statements, FY25 and FY24; includes MD&A): https://cdn.vanderbilt.edu/vu-sub/wp-content/uploads/sites/291/2025/10/01145328/2025_VU_Financial_Report.pdf; FY24 Vanderbilt Financial Report (FY24 and FY23): https://cdn.vanderbilt.edu/vu-sub/wp-content/uploads/sites/291/2024/11/07201434/2024_VU_Financial_Report.pdf
A13: Northwestern | B13: Salaries and wages | D13: Not separately reported. 'Salaries, wages, and benefits 1,997,951 1,832,098' (thousands), FY25 report PDF p.11 (printed p.9); note 16 (PDF p.34) also combined. | E13: FY25 Northwestern University Financial Report (audited consolidated financial statements, FY25 and FY24): https://www.northwestern.edu/financial-operations/annual-financial-reports/2025-financial-report.pdf; FY24 Northwestern University Financial Report (FY24 and FY23): https://www.northwestern.edu/financial-operations/annual-financial-reports/2024-financial-report.pdf
A14: Northwestern | B14: Total operating expenses | C14: 3607255000 | D14: 'Total operating expenses 3,607,255 3,273,487' (thousands), FY25 report PDF p.11. | E14: FY25 Northwestern University Financial Report (audited consolidated financial statements, FY25 and FY24): https://www.northwestern.edu/financial-operations/annual-financial-reports/2025-financial-report.pdf; FY24 Northwestern University Financial Report (FY24 and FY23): https://www.northwestern.edu/financial-operations/annual-financial-reports/2024-financial-report.pdf
A15: Northwestern | B15: Depreciation | C15: 216713000 | D15: 'Depreciation 216,713 212,024' (thousands), separate operating line, FY25 report PDF p.11. | E15: FY25 Northwestern University Financial Report (audited consolidated financial statements, FY25 and FY24): https://www.northwestern.edu/financial-operations/annual-financial-reports/2025-financial-report.pdf; FY24 Northwestern University Financial Report (FY24 and FY23): https://www.northwestern.edu/financial-operations/annual-financial-reports/2024-financial-report.pdf
A16: Northwestern | B16: Interest | C16: 99478000 | D16: 'Interest on indebtedness 99,478 92,985' (thousands), separate operating line, FY25 report PDF p.11. | E16: FY25 Northwestern University Financial Report (audited consolidated financial statements, FY25 and FY24): https://www.northwestern.edu/financial-operations/annual-financial-reports/2025-financial-report.pdf; FY24 Northwestern University Financial Report (FY24 and FY23): https://www.northwestern.edu/financial-operations/annual-financial-reports/2024-financial-report.pdf
A17: Princeton | B17: Salaries and wages | C17: 1162823000 | D17: 'Salaries and wages 1,162,823 - 1,162,823' (Consolidated Statements of Activities, Year ended June 30, 2025, operating expenses, $ thousands; FY25 audited statements PDF p5; also Report of the Treasurer 2024-25 PDF p42). Note 15 natural x functional table: 'Salaries and wages $ 705,059 $ 96,485 $ 258,040 $ 103,239 $ 1,162,823' (PDF p31). | E17: FY25 audited consolidated financial statements, June 30, 2025 and 2024: https://finance.princeton.edu/sites/g/files/toruqf151/files/documents/Financial%20Statements%20FY2025.pdf; Report of the Treasurer 2024-25 (includes the audited FY25/FY24 statements; highlights table with enrollment on PDF p2; MD&A printed p.30-31): https://finance.princeton.edu/sites/g/files/toruqf8101/files/documents/2024-25%20Report%20of%20the%20Treasurer%20Final.pdf
A18: Princeton | B18: Total operating expenses | C18: 2744548000 | D18: 'Total operating expenses 2,744,548 - 2,744,548' (PDF p5). Natural sum 1,162,823+351,760+551,402+113,819+111,451+231,467+221,826 = 2,744,548. Note 15 total also 2,744,548. Excluded from operating: 'Net periodic benefit cost other than service cost' 11,110 (nonoperating; Note 15 total incl. nonoperating 2,755,658). | E18: FY25 audited consolidated financial statements, June 30, 2025 and 2024: https://finance.princeton.edu/sites/g/files/toruqf151/files/documents/Financial%20Statements%20FY2025.pdf; Report of the Treasurer 2024-25 (includes the audited FY25/FY24 statements; highlights table with enrollment on PDF p2; MD&A printed p.30-31): https://finance.princeton.edu/sites/g/files/toruqf8101/files/documents/2024-25%20Report%20of%20the%20Treasurer%20Final.pdf
A19: Princeton | B19: Depreciation | C19: 231467000 | D19: 'Depreciation 231,467 - 231,467' (PDF p5); cash flow 'Depreciation expense 231,467 210,883' (PDF p7). | E19: FY25 audited consolidated financial statements, June 30, 2025 and 2024: https://finance.princeton.edu/sites/g/files/toruqf151/files/documents/Financial%20Statements%20FY2025.pdf; Report of the Treasurer 2024-25 (includes the audited FY25/FY24 statements; highlights table with enrollment on PDF p2; MD&A printed p.30-31): https://finance.princeton.edu/sites/g/files/toruqf8101/files/documents/2024-25%20Report%20of%20the%20Treasurer%20Final.pdf
A20: Princeton | B20: Interest | C20: 221826000 | D20: 'Interest on indebtedness 221,826 - 221,826' (PDF p5). Cash flow supplemental: 'Interest paid $ 233,141 $ 166,293' (PDF p7). Report of the Treasurer 2024-25 (printed p.30): 'Depreciation and interest grew 10 percent and 67 percent, respectively, due to the opening of new facilities and increased borrowing to fund the capital plan.' | E20: FY25 audited consolidated financial statements, June 30, 2025 and 2024: https://finance.princeton.edu/sites/g/files/toruqf151/files/documents/Financial%20Statements%20FY2025.pdf; Report of the Treasurer 2024-25 (includes the audited FY25/FY24 statements; highlights table with enrollment on PDF p2; MD&A printed p.30-31): https://finance.princeton.edu/sites/g/files/toruqf8101/files/documents/2024-25%20Report%20of%20the%20Treasurer%20Final.pdf
A21: Harvard | B21: Salaries and wages | D21: NOT EXTRACTED: the Harvard Financial Report PDFs could not be retrieved (finance.harvard.edu returns Akamai 'Access Denied' 403 to curl with a browser User-Agent, and WebFetch reports the host blocked by the network egress proxy). No number was taken from a search snippet or memory. | E21: FY25 Harvard University Financial Report (located, NOT retrieved: 403): https://finance.harvard.edu/sites/g/files/omnuum12671/files/2025-10/fy25-financial-report.pdf; FY25 Financial Overview from the VP for Finance and the Treasurer (located, NOT retrieved: 403): https://finance.harvard.edu/sites/g/files/omnuum12671/files/2025-10/fy25-financial-overview.pdf
A22: Harvard | B22: Total operating expenses | D22: NOT EXTRACTED: the Harvard Financial Report PDFs could not be retrieved (finance.harvard.edu returns Akamai 'Access Denied' 403 to curl with a browser User-Agent, and WebFetch reports the host blocked by the network egress proxy). No number was taken from a search snippet or memory. | E22: FY25 Harvard University Financial Report (located, NOT retrieved: 403): https://finance.harvard.edu/sites/g/files/omnuum12671/files/2025-10/fy25-financial-report.pdf; FY25 Financial Overview from the VP for Finance and the Treasurer (located, NOT retrieved: 403): https://finance.harvard.edu/sites/g/files/omnuum12671/files/2025-10/fy25-financial-overview.pdf
A23: Harvard | B23: Depreciation | D23: NOT EXTRACTED: the Harvard Financial Report PDFs could not be retrieved (finance.harvard.edu returns Akamai 'Access Denied' 403 to curl with a browser User-Agent, and WebFetch reports the host blocked by the network egress proxy). No number was taken from a search snippet or memory. | E23: FY25 Harvard University Financial Report (located, NOT retrieved: 403): https://finance.harvard.edu/sites/g/files/omnuum12671/files/2025-10/fy25-financial-report.pdf; FY25 Financial Overview from the VP for Finance and the Treasurer (located, NOT retrieved: 403): https://finance.harvard.edu/sites/g/files/omnuum12671/files/2025-10/fy25-financial-overview.pdf
A24: Harvard | B24: Interest | D24: NOT EXTRACTED: the Harvard Financial Report PDFs could not be retrieved (finance.harvard.edu returns Akamai 'Access Denied' 403 to curl with a browser User-Agent, and WebFetch reports the host blocked by the network egress proxy). No number was taken from a search snippet or memory. | E24: FY25 Harvard University Financial Report (located, NOT retrieved: 403): https://finance.harvard.edu/sites/g/files/omnuum12671/files/2025-10/fy25-financial-report.pdf; FY25 Financial Overview from the VP for Finance and the Treasurer (located, NOT retrieved: 403): https://finance.harvard.edu/sites/g/files/omnuum12671/files/2025-10/fy25-financial-overview.pdf
A25: Yale | B25: Salaries and wages | C25: 2737371000 | D25: 'Salaries and wages $ 2,737,371 $ - $ 2,737,371 $ 2,546,768' (Yale University Consolidated Statement of Activities, year ended June 30, 2025, $ thousands; FY25 Financial Report PDF p24 = printed p.22). Same figure in Note 14 (PDF p61). | E25: Yale University Financial Report 2024-2025 (audited consolidated financial statements; issued October 23, 2025): https://your.yale.edu/media/3134/download?inline=; Yale University Financial Report 2023-2024 (audited consolidated financial statements): https://your.yale.edu/sites/default/files/2025-04/fy24_annual_financial_report.pdf
A26: Yale | B26: Total operating expenses | C26: 5807911000 | D26: 'Total expenses 5,807,911 - 5,807,911 5,412,254' (operating section, 'Expenses:', FY25 report PDF p24). Sum of natural lines 2,737,371+861,635+504,923+1,703,982 = 5,807,911. Note 14 'Total operating expenses $ 5,807,911' (PDF p61). MD&A: 'Operating expenses totaled $5.8 billion for 2025'. | E26: Yale University Financial Report 2024-2025 (audited consolidated financial statements; issued October 23, 2025): https://your.yale.edu/media/3134/download?inline=; Yale University Financial Report 2023-2024 (audited consolidated financial statements): https://your.yale.edu/sites/default/files/2025-04/fy24_annual_financial_report.pdf
A27: Yale | B27: Depreciation | D27: Not separate on the face. Combined row: 'Depreciation, amortization and interest 504,923 - 504,923 470,601' (PDF p24). Note 8: 'Depreciation expense included in operating expenses amounted to $344.8 million and $328.9 million in 2025 and 2024' (PDF p48, printed p.46). | E27: Yale University Financial Report 2024-2025 (audited consolidated financial statements; issued October 23, 2025): https://your.yale.edu/media/3134/download?inline=; Yale University Financial Report 2023-2024 (audited consolidated financial statements): https://your.yale.edu/sites/default/files/2025-04/fy24_annual_financial_report.pdf
A28: Yale | B28: Interest | D28: Not separate on the face (combined row above). Note 10: 'Total interest expense incurred on indebtedness was $108.3 million and $111.3 million in 2025 and 2024, respectively. Interest capitalized to land, buildings and equipment totaled $14.4 million and $9.9 million ... Amortization expense related to bond issue costs included in operating expenses amounted to $3.0 million and $3.7 million' (PDF p52). Note 6: financing lease 'Interest on lease liabilities Depreciation, amortization and interest 12,877 6,213' (PDF p46). | E28: Yale University Financial Report 2024-2025 (audited consolidated financial statements; issued October 23, 2025): https://your.yale.edu/media/3134/download?inline=; Yale University Financial Report 2023-2024 (audited consolidated financial statements): https://your.yale.edu/sites/default/files/2025-04/fy24_annual_financial_report.pdf
A29: Chicago | B29: Salaries and wages | C29: 3678678000 | D29: Academic salaries 923,520 + Staff salaries 2,755,158 = 3,678,678 (thousands), 2025 column, under Expenses > Compensation on the Consolidated Statements of Activities (Benefits shown separately at 839,139). FY25 report, printed p.4 (PDF p.6). Consolidated, so includes UChicago Medical Center staff salaries. | E29: FY25 audited consolidated financial statements (The University of Chicago, June 30, 2025 and 2024): https://intranet.uchicago.edu/-/media/project/uchicago-tenant/intranet/fna/financial-services/accounting-and-treasury/audited-financial-statements/2024-2025-the; FY24 audited consolidated financial statements (June 30, 2024 and 2023): https://intranet.uchicago.edu/-/media/project/uchicago-tenant/intranet/fna/financial-services/accounting-and-treasury/audited-financial-statements/2023-2024-the
A30: Chicago | B30: Total operating expenses | C30: 8283042000 | D30: 'Total operating expenses 8,283,042' (thousands), 2025 column, Operating section of Consolidated Statements of Activities. FY25 report, printed p.4 (PDF p.6). | E30: FY25 audited consolidated financial statements (The University of Chicago, June 30, 2025 and 2024): https://intranet.uchicago.edu/-/media/project/uchicago-tenant/intranet/fna/financial-services/accounting-and-treasury/audited-financial-statements/2024-2025-the; FY24 audited consolidated financial statements (June 30, 2024 and 2023): https://intranet.uchicago.edu/-/media/project/uchicago-tenant/intranet/fna/financial-services/accounting-and-treasury/audited-financial-statements/2023-2024-the
A31: Chicago | B31: Depreciation | C31: 401386000 | D31: 'Depreciation 401,386' (thousands) under Other operating expenses. FY25 report, printed p.4 (PDF p.6). | E31: FY25 audited consolidated financial statements (The University of Chicago, June 30, 2025 and 2024): https://intranet.uchicago.edu/-/media/project/uchicago-tenant/intranet/fna/financial-services/accounting-and-treasury/audited-financial-statements/2024-2025-the; FY24 audited consolidated financial statements (June 30, 2024 and 2023): https://intranet.uchicago.edu/-/media/project/uchicago-tenant/intranet/fna/financial-services/accounting-and-treasury/audited-financial-statements/2023-2024-the
A32: Chicago | B32: Interest | C32: 215170000 | D32: 'Interest 215,170' (thousands) under Other operating expenses. FY25 report, printed p.4 (PDF p.6). | E32: FY25 audited consolidated financial statements (The University of Chicago, June 30, 2025 and 2024): https://intranet.uchicago.edu/-/media/project/uchicago-tenant/intranet/fna/financial-services/accounting-and-treasury/audited-financial-statements/2024-2025-the; FY24 audited consolidated financial statements (June 30, 2024 and 2023): https://intranet.uchicago.edu/-/media/project/uchicago-tenant/intranet/fna/financial-services/accounting-and-treasury/audited-financial-statements/2023-2024-the
A33: Duke | B33: Salaries and wages | C33: 5041664000 | D33: 'Salaries and wages 5,041,664' (thousands), 2025 column, Operating expenses on the Consolidated Statements of Activities; 'Employee benefits 1,189,048' is a separate line. FY25 report (Financial Statements 2024/2025), printed p.14 (PDF p.16). Consolidated with DUHS, so includes health system staff. | E33: FY25 Duke University audited consolidated financial statements (Financial Statements 2024/2025): https://resources.finance.duke.edu/resources/docs/Financial_Reports2024-25.pdf; FY24 Duke University audited consolidated financial statements (Financial Statements 2023/2024): https://resources.finance.duke.edu/resources/docs/Financial_Reports2023-24.pdf
A34: Duke | B34: Total operating expenses | C34: 10953208000 | D34: 'Total operating expenses 10,953,208' (thousands), 2025 column. FY25 report (Financial Statements 2024/2025), printed p.14 (PDF p.16). | E34: FY25 Duke University audited consolidated financial statements (Financial Statements 2024/2025): https://resources.finance.duke.edu/resources/docs/Financial_Reports2024-25.pdf; FY24 Duke University audited consolidated financial statements (Financial Statements 2023/2024): https://resources.finance.duke.edu/resources/docs/Financial_Reports2023-24.pdf
A35: Duke | B35: Depreciation | C35: 471677000 | D35: 'Depreciation and amortization 471,677' (thousands), 2025 column, in Operating expenses. FY25 report (Financial Statements 2024/2025), printed p.14 (PDF p.16). | E35: FY25 Duke University audited consolidated financial statements (Financial Statements 2024/2025): https://resources.finance.duke.edu/resources/docs/Financial_Reports2024-25.pdf; FY24 Duke University audited consolidated financial statements (Financial Statements 2023/2024): https://resources.finance.duke.edu/resources/docs/Financial_Reports2023-24.pdf
A36: Duke | B36: Interest | C36: 161512000 | D36: 'Interest expense 161,512' (thousands), 2025 column, in Operating expenses. FY25 report (Financial Statements 2024/2025), printed p.14 (PDF p.16). | E36: FY25 Duke University audited consolidated financial statements (Financial Statements 2024/2025): https://resources.finance.duke.edu/resources/docs/Financial_Reports2024-25.pdf; FY24 Duke University audited consolidated financial statements (Financial Statements 2023/2024): https://resources.finance.duke.edu/resources/docs/Financial_Reports2023-24.pdf
